Workbook

Sheet Diccionario Nombre científicos
A1: Asignado a | B1: Contrato de Origen | C1: Item | D1: Nombre Científico corregido | E1: Nombre común | F1: Familia | G1: _# Emparejamiento | H1: _# de familia | I1: Nombre científico sin # | J1: Nombre Científico con # | K1: Nombre común sin # | L1: Nombre común con # | M1: Origen | N1: ¿Hay reportes en Colombia? | O1: Hábito | P1: Género sin # | Q1: Altura en desarrollo pleno (m) | R1: Fuente (altura) | S1: Diametro en desarrollo pleno (cm) | T1: Fuente | U1: Tasa de crecimiento (Rápida, Media, Lenta- No encontrada) | V1: Densidad promedio de la madera ( o no encontrada) (g/cm3) | W1: Tamaño de los frutos (mm) | X1: Observaciones
A2: Leiner Victoria | B2: Todos | C2: 0 | D2: Indeterminado | E2: Indeterminado | F2: Indeterminado | G2: 0 | H2: 0 | I2: =D2 -> Indeterminado | J2: 00 Indeterminado | K2: Indeterminado | L2: 00 Indeterminado | M2: Indeterminado | N2: No | O2: Indeterminado | P2: Indeterminado | Q2: 0 | R2: Consultar | S2: 0 | T2: Consultar | U2: Consultar | V2: Consultar
A3: LAURA RENGIFO | B3: Podas Sur | C3: 1 | D3: Abarema jupunba | E3: Frijolillo; Rayo; Guacamayo Blanco; Carbonero; Arenillo de Monte Chocho | F3: Fabaceae | G3: 1 | H3: =VLOOKUP(F3,'Generos y Familia'!$A$1:$C$623,2,FALSE) -> 27 | I3: =D3 -> Abarema jupunba | J3: =G3&" "&D3 -> 1 Abarema jupunba | K3: =E3 -> Frijolillo; Rayo; Guacamayo Blanco; Carbonero; Arenillo de Monte Chocho | L3: =G3&" "&E3 -> 1 Frijolillo; Rayo; Guacamayo Blanco; Carbonero; Arenillo de Monte Chocho | M3: Nativa | N3: Si | O3: Árbol | P3: Abarema | Q3: 20 | R3: (UEIA, 2014) | S3: 60 | T3: (UEIA, 2014) | U3: Media | V3: 0.55 | X3: Diámetro y/o altura aproximado por género
A4: LAURA RENGIFO | B4: Podas Sur | C4: 2 | D4: Abarema sp | E4: Abarema | F4: Fabaceae | G4: 2 | H4: =VLOOKUP(F4,'Generos y Familia'!$A$1:$C$623,2,FALSE) -> 27 | I4: =D4 -> Abarema sp | J4: =G4&" "&D4 -> 2 Abarema sp | K4: =E4 -> Abarema | L4: =G4&" "&E4 -> 2 Abarema | M4: Nativa | N4: Si | O4: Árbol | P4: Abarema | Q4: 20 | S4: 60 | U4: Media
A5: LAURA RENGIFO | B5: Podas Sur | C5: 3 | D5: Abelmoschus moschatus | E5: Hibisco | F5: Malvaceae | G5: 3 | H5: =VLOOKUP(F5,'Generos y Familia'!$A$1:$C$623,2,FALSE) -> 40 | I5: =D5 -> Abelmoschus moschatus | J5: =G5&" "&D5 -> 3 Abelmoschus moschatus | K5: =E5 -> Hibisco | L5: =G5&" "&E5 -> 3 Hibisco | M5: Introducida | N5: Si | O5: Arbusto | P5: Abelmoschus
A6: LAURA RENGIFO | B6: Podas Sur | C6: 4 | D6: Abutilon insigne | E6: Abutilon | F6: Malvaceae | G6: 4 | H6: =VLOOKUP(F6,'Generos y Familia'!$A$1:$C$623,2,FALSE) -> 40 | I6: =D6 -> Abutilon insigne | J6: =G6&" "&D6 -> 4 Abutilon insigne | K6: =E6 -> Abutilon | L6: =G6&" "&E6 -> 4 Abutilon | M6: Nativa | N6: Si | O6: Arbusto | P6: Abutilon | Q6: 3 | R6: (UEIA, 2014) | U6: Media
A7: LAURA RENGIFO | B7: Podas Sur | C7: 5 | D7: Abutilon pictum | E7: Faroolito Japones | F7: Malvaceae | G7: 5 | H7: =VLOOKUP(F7,'Generos y Familia'!$A$1:$C$623,2,FALSE) -> 40 | I7: =D7 -> Abutilon pictum | J7: =G7&" "&D7 -> 5 Abutilon pictum | K7: =E7 -> Faroolito Japones | L7: =G7&" "&E7 -> 5 Faroolito Japones | M7: Introducida | N7: Si | O7: Arbusto | P7: Abutilon | Q7: 3 | R7: (UEIA & USFS, 2018) | S7: 30 | U7: Rápida | X7: Diámetro y/o altura aproximado por género
A8: LAURA RENGIFO | B8: Podas Sur | C8: 6 | D8: Abutilon sp | E8: Abutilon | F8: Malvaceae | G8: 6 | H8: =VLOOKUP(F8,'Generos y Familia'!$A$1:$C$623,2,FALSE) -> 40 | I8: =D8 -> Abutilon sp | J8: =G8&" "&D8 -> 6 Abutilon sp | K8: =E8 -> Abutilon | L8: =G8&" "&E8 -> 6 Abutilon | M8: Nativa | N8: Si | O8: Arbusto | P8: Abutilon | Q8: 3 | R8: (UEIA, 2014) | U8: Media | X8: Diámetro y/o altura aproximado por género
A9: LAURA RENGIFO | B9: Podas Sur | C9: 7 | D9: Acacia angustissima | E9: Dormilón | F9: Fabaceae | G9: 7 | H9: =VLOOKUP(F9,'Generos y Familia'!$A$1:$C$623,2,FALSE) -> 27 | I9: =D9 -> Acacia angustissima | J9: =G9&" "&D9 -> 7 Acacia angustissima | K9: =E9 -> Dormilón | L9: =G9&" "&E9 -> 7 Dormilón | M9: Nativa | N9: Si | O9: Arbusto | P9: Acacia | Q9: 6 | R9: (UEIA & USFS, 2018) | S9: 30 | U9: Rápida | X9: Diámetro y/o altura aproximado por género
A10: LAURA RENGIFO | B10: Podas Sur | C10: 8 | D10: Acacia baileyana | E10: Acacia (Baileyana) | F10: Fabaceae | G10: 8 | H10: =VLOOKUP(F10,'Generos y Familia'!$A$1:$C$623,2,FALSE) -> 27 | I10: =D10 -> Acacia baileyana | J10: =G10&" "&D10 -> 8 Acacia baileyana | K10: =E10 -> Acacia (Baileyana) | L10: =G10&" "&E10 -> 8 Acacia (Baileyana) | M10: Introducida | N10: Si | O10: Árbol | P10: Acacia | Q10: 5 | R10: (UEIA & USFS, 2018) | S10: 70 | U10: Rápida | X10: Diámetro y/o altura aproximado por género
A11: LAURA RENGIFO | B11: Clus Cartago | C11: 9 | D11: Acacia caven | E11: Aromo | F11: Fabaceae | G11: 9 | H11: =VLOOKUP(F11,'Generos y Familia'!$A$1:$C$623,2,FALSE) -> 27 | I11: =D11 -> Acacia caven | J11: =G11&" "&D11 -> 9 Acacia caven | K11: =E11 -> Aromo | L11: =G11&" "&E11 -> 9 Aromo | M11: Nativa | N11: No | O11: Arbusto | P11: Acacia | Q11: 6 | R11: (Benedetti, 2012) | S11: 40 | T11: (Benedetti, 2012) | U11: Rápida | V11: 0.83 | W11: 30-100
A12: LAURA RENGIFO | B12: Podas Sur | C12: 10 | D12: Acacia decurrens | E12: Acacia Roja (Decurrens) | F12: Fabaceae | G12: 10 | H12: =VLOOKUP(F12,'Generos y Familia'!$A$1:$C$623,2,FALSE) -> 27 | I12: =D12 -> Acacia decurrens | J12: =G12&" "&D12 -> 10 Acacia decurrens | K12: =E12 -> Acacia Roja (Decurrens) | L12: =G12&" "&E12 -> 10 Acacia Roja (Decurrens) | M12: Introducida | N12: Si | O12: Árbol | P12: Acacia | Q12: 15 | R12: (UEIA, 2014) | S12: 60 | T12: (UEIA, 2014) | U12: Rápida | X12: Diámetro y/o altura aproximado por género
A13: LAURA RENGIFO | B13: Clus Cartago | C13: 11 | D13: Acacia farnesiana | E13: Acacia de Desierto; Acacia Farnesiana | F13: Fabaceae | G13: 11 | H13: =VLOOKUP(F13,'Generos y Familia'!$A$1:$C$623,2,FALSE) -> 27 | I13: =D13 -> Acacia farnesiana | J13: =G13&" "&D13 -> 11 Acacia farnesiana | K13: =E13 -> Acacia de Desierto; Acacia Farnesiana | L13: =G13&" "&E13 -> 11 Acacia de Desierto; Acacia Farnesiana | M13: Nativa | N13: Si | O13: Árbol | P13: Acacia | Q13: 2 | R13: (UEIA, 2014) | U13: Lenta
A14: LAURA RENGIFO | B14: Podas Sur | C14: 12 | D14: Acacia mangium | E14: Acacia Mangium | F14: Fabaceae | G14: 12 | H14: =VLOOKUP(F14,'Generos y Familia'!$A$1:$C$623,2,FALSE) -> 27 | I14: =D14 -> Acacia mangium | J14: =G14&" "&D14 -> 12 Acacia mangium | K14: =E14 -> Acacia Mangium | L14: =G14&" "&E14 -> 12 Acacia Mangium | M14: Introducida | N14: Si | O14: Árbol | P14: Acacia | Q14: 30 | R14: (UEIA & USFS, 2018) | S14: 60 | T14: (UEIA, 2014) | U14: Rápida | V14: 0.65
A15: LAURA RENGIFO | B15: Podas Sur | C15: 13 | D15: Acacia melanoxylon | E15: Acacia Japonesa; Acacia Negra | F15: Fabaceae | G15: 13 | H15: =VLOOKUP(F15,'Generos y Familia'!$A$1:$C$623,2,FALSE) -> 27 | I15: =D15 -> Acacia melanoxylon | J15: =G15&" "&D15 -> 13 Acacia melanoxylon | K15: =E15 -> Acacia Japonesa; Acacia Negra | L15: =G15&" "&E15 -> 13 Acacia Japonesa; Acacia Negra | M15: Introducida | N15: Si | O15: Árbol | P15: Acacia | Q15: 20 | R15: (UEIA, 2014) | S15: 50 | T15: (UEIA, 2014) | U15: Rápida | V15: 0.54 | W15: 70-100
A16: LAURA RENGIFO | B16: Podas Sur | C16: 14 | D16: Acacia muricata | E16: Acacia | F16: Fabaceae | G16: 14 | H16: =VLOOKUP(F16,'Generos y Familia'!$A$1:$C$623,2,FALSE) -> 27 | I16: =D16 -> Acacia muricata | J16: =G16&" "&D16 -> 14 Acacia muricata | K16: =E16 -> Acacia | L16: =G16&" "&E16 -> 14 Acacia | M16: Introducida | N16: No | O16: Árbol | P16: Acacia
A17: LAURA RENGIFO | B17: Podas Sur | C17: 15 | D17: Acalypha amentacea | E17: Acalifa Repollo; Carlota | F17: Euphorbiaceae | G17: 15 | H17: =VLOOKUP(F17,'Generos y Familia'!$A$1:$C$623,2,FALSE) -> 26 | I17: =D17 -> Acalypha amentacea | J17: =G17&" "&D17 -> 15 Acalypha amentacea | K17: =E17 -> Acalifa Repollo; Carlota | L17: =G17&" "&E17 -> 15 Acalifa Repollo; Carlota | M17: Introducida | N17: Si | O17: Arbusto | P17: Acalypha | Q17: 3 | R17: (UEIA & USFS, 2018)
A18: LAURA RENGIFO | B18: Podas Sur | C18: 16 | D18: Acalypha diversifolia | E18: Carlota | F18: Euphorbiaceae | G18: 16 | H18: =VLOOKUP(F18,'Generos y Familia'!$A$1:$C$623,2,FALSE) -> 26 | I18: =D18 -> Acalypha diversifolia | J18: =G18&" "&D18 -> 16 Acalypha diversifolia | K18: =E18 -> Carlota | L18: =G18&" "&E18 -> 16 Carlota | M18: Nativa | N18: Si | O18: Arbusto | P18: Acalypha
A19: LAURA RENGIFO | B19: Podas Sur | C19: 17 | D19: Acalypha hispida | E19: Cola de Zorro | F19: Euphorbiaceae | G19: 17 | H19: =VLOOKUP(F19,'Generos y Familia'!$A$1:$C$623,2,FALSE) -> 26 | I19: =D19 -> Acalypha hispida | J19: =G19&" "&D19 -> 17 Acalypha hispida | K19: =E19 -> Cola de Zorro | L19: =G19&" "&E19 -> 17 Cola de Zorro | M19: Introducida | N19: Si | O19: Arbusto | P19: Acalypha | Q19: 4 | R19: (UEIA & USFS, 2018) | U19: Rápida
A20: LAURA RENGIFO | B20: Podas Sur | C20: 18 | D20: Acalypha macrostachya | E20: Ortiga | F20: Euphorbiaceae | G20: 18 | H20: =VLOOKUP(F20,'Generos y Familia'!$A$1:$C$623,2,FALSE) -> 26 | I20: =D20 -> Acalypha macrostachya | J20: =G20&" "&D20 -> 18 Acalypha macrostachya | K20: =E20 -> Ortiga | L20: =G20&" "&E20 -> 18 Ortiga | M20: Nativa | N20: Si | O20: Arbusto | P20: Acalypha | Q20: 6 | R20: (UEIA & USFS, 2018) | U20: Rápida
A21: LAURA RENGIFO | B21: Podas Sur | C21: 19 | D21: Acalypha villosa | E21: Vara de Alcalde; Salvia de Monte | F21: Euphorbiaceae | G21: 19 | H21: =VLOOKUP(F21,'Generos y Familia'!$A$1:$C$623,2,FALSE) -> 26 | I21: =D21 -> Acalypha villosa | J21: =G21&" "&D21 -> 19 Acalypha villosa | K21: =E21 -> Vara de Alcalde; Salvia de Monte | L21: =G21&" "&E21 -> 19 Vara de Alcalde; Salvia de Monte | M21: Introducida | N21: Si | O21: Arbusto | P21: Acalypha
A22: LAURA RENGIFO | B22: Podas Sur | C22: 20 | D22: Acalypha wilkesiana | E22: Carlota | F22: Euphorbiaceae | G22: 20 | H22: =VLOOKUP(F22,'Generos y Familia'!$A$1:$C$623,2,FALSE) -> 26 | I22: =D22 -> Acalypha wilkesiana | J22: =G22&" "&D22 -> 20 Acalypha wilkesiana | K22: =E22 -> Carlota | L22: =G22&" "&E22 -> 20 Carlota | M22: Introducida | N22: Si | O22: Arbusto | P22: Acalypha | Q22: 3 | R22: (UEIA & USFS, 2018) | U22: Rápida
A23: LAURA RENGIFO | B23: Podas Sur | C23: 21 | D23: Acca sellowiana | E23: Guayaba Feijoa | F23: Myrtaceae | G23: 21 | H23: =VLOOKUP(F23,'Generos y Familia'!$A$1:$C$623,2,FALSE) -> 49 | I23: =D23 -> Acca sellowiana | J23: =G23&" "&D23 -> 21 Acca sellowiana | K23: =E23 -> Guayaba Feijoa | L23: =G23&" "&E23 -> 21 Guayaba Feijoa | M23: Nativa | N23: Si | O23: Arbusto | P23: Acca | Q23: 5 | R23: (UEIA, 2014) | S23: 20 | T23: (UEIA, 2014) | U23: Lenta
A24: LAURA RENGIFO | B24: Clus Cartago | C24: 22 | D24: Achatocarpus nigricans | E24: Totocal O Limon Macho | F24: Achatocarpaceae | G24: 22 | H24: =VLOOKUP(F24,'Generos y Familia'!$A$1:$C$623,2,FALSE) -> 2 | I24: =D24 -> Achatocarpus nigricans | J24: =G24&" "&D24 -> 22 Achatocarpus nigricans | K24: =E24 -> Totocal O Limon Macho | L24: =G24&" "&E24 -> 22 Totocal O Limon Macho | M24: Nativa | N24: Si | O24: Árbol | P24: Achatocarpus | Q24: 12 | R24: (UEIA & USFS, 2018) | U24: Rápida
A25: LAURA RENGIFO | B25: Podas Sur | C25: 23 | D25: Iochroma arborescens | E25: Güitite; Tabalgue; Tomatoquina | F25: Solanaceae | G25: 23 | H25: =VLOOKUP(F25,'Generos y Familia'!$A$1:$C$623,2,FALSE) -> 89 | I25: =D25 -> Iochroma arborescens | J25: =G25&" "&D25 -> 23 Iochroma arborescens | K25: =E25 -> Güitite; Tabalgue; Tomatoquina | L25: =G25&" "&E25 -> 23 Güitite; Tabalgue; Tomatoquina | M25: Nativa | N25: Si | O25: Árbol | P25: Acnistus | Q25: 8 | R25: (iNaturalistCO, 2024) | S25: 25 | U25: Rápida | W25: 5-6 | X25: Diámetro y/o altura aproximado por género
A26: LAURA RENGIFO | B26: Clus Cartago | C26: 24 | D26: Acosmium dasycarpum | E26: Tasaa | F26: Fabaceae | G26: 24 | H26: =VLOOKUP(F26,'Generos y Familia'!$A$1:$C$623,2,FALSE) -> 27 | I26: =D26 -> Acosmium dasycarpum | J26: =G26&" "&D26 -> 24 Acosmium dasycarpum | K26: =E26 -> Tasaa | L26: =G26&" "&E26 -> 24 Tasaa | M26: Nativa | N26: Si | O26: Arbusto | P26: Acosmium
A27: LAURA RENGIFO | B27: Podas Sur | C27: 25 | D27: Acrocarpus fraxinifolius | E27: Cedro Rosado de la India | F27: Fabaceae | G27: 25 | H27: =VLOOKUP(F27,'Generos y Familia'!$A$1:$C$623,2,FALSE) -> 27 | I27: =D27 -> Acrocarpus fraxinifolius | J27: =G27&" "&D27 -> 25 Acrocarpus fraxinifolius | K27: =E27 -> Cedro Rosado de la India | L27: =G27&" "&E27 -> 25 Cedro Rosado de la India | M27: Introducida | N27: No | O27: Árbol | P27: Acrocarpus | Q27: 25 | R27: (UEIA & USFS, 2018) | U27: Rápida
A28: LAURA RENGIFO | B28: Podas Sur | C28: 26 | D28: Acrocomia aculeata | E28: Palma Chonta; Corozo Baboso | F28: Arecaceae | G28: 26 | H28: =VLOOKUP(F28,'Generos y Familia'!$A$1:$C$623,2,FALSE) -> 14 | I28: =D28 -> Acrocomia aculeata | J28: =G28&" "&D28 -> 26 Acrocomia aculeata | K28: =E28 -> Palma Chonta; Corozo Baboso | L28: =G28&" "&E28 -> 26 Palma Chonta; Corozo Baboso | M28: Nativa | N28: Si | O28: Palma | P28: Acrocomia | Q28: 15 | R28: (UEIA, 2014) | S28: 30 | T28: (UEIA, 2014) | U28: Media | W28: 29,6
A29: LAURA RENGIFO | B29: Podas Sur | C29: 27 | D29: Adenanthera pavonina | E29: Coralito; Chocho | F29: Fabaceae | G29: 27 | H29: =VLOOKUP(F29,'Generos y Familia'!$A$1:$C$623,2,FALSE) -> 27 | I29: =D29 -> Adenanthera pavonina | J29: =G29&" "&D29 -> 27 Adenanthera pavonina | K29: =E29 -> Coralito; Chocho | L29: =G29&" "&E29 -> 27 Coralito; Chocho | M29: Introducida | N29: Si | O29: Árbol | P29: Adenanthera | Q29: 15 | R29: (UEIA, 2014) | S29: 45 | T29: (UEIA, 2014) | U29: Rápida | V29: 0.68
A30: LAURA RENGIFO | B30: Podas Sur | C30: 28 | D30: Adenaria floribunda | E30: Chaparro | F30: Lythraceae | G30: 28 | H30: =VLOOKUP(F30,'Generos y Familia'!$A$1:$C$623,2,FALSE) -> 37 | I30: =D30 -> Adenaria floribunda | J30: =G30&" "&D30 -> 28 Adenaria floribunda | K30: =E30 -> Chaparro | L30: =G30&" "&E30 -> 28 Chaparro | M30: Nativa | N30: Si | O30: Arbusto | P30: Adenaria | Q30: 7 | R30: (UEIA, 2014) | S30: 10 | T30: (UEIA, 2014) | U30: Rápida
A31: LAURA RENGIFO | B31: Podas Sur | C31: 29 | D31: Adonidia merrillii | E31: Palma de Manila; Palma de Navidad | F31: Arecaceae | G31: 29 | H31: =VLOOKUP(F31,'Generos y Familia'!$A$1:$C$623,2,FALSE) -> 14 | I31: =D31 -> Adonidia merrillii | J31: =G31&" "&D31 -> 29 Adonidia merrillii | K31: =E31 -> Palma de Manila; Palma de Navidad | L31: =G31&" "&E31 -> 29 Palma de Manila; Palma de Navidad | M31: Introducida | N31: Si | O31: Palma | P31: Adonidia | Q31: 12 | R31: (UEIA, 2014) | S31: 20 | T31: (UEIA, 2014) | U31: Media | W31: 30
A32: LAURA RENGIFO | B32: Podas Sur | C32: 30 | D32: Aegiceras corniculatum | E32: Aegiceras Corniculatum | F32: Primulaceae | G32: 30 | H32: =VLOOKUP(F32,'Generos y Familia'!$A$1:$C$623,2,FALSE) -> 74 | I32: =D32 -> Aegiceras corniculatum | J32: =G32&" "&D32 -> 30 Aegiceras corniculatum | K32: =E32 -> Aegiceras Corniculatum | L32: =G32&" "&E32 -> 30 Aegiceras Corniculatum | M32: Introducida | N32: No | O32: Arbusto | P32: Aegiceras
A33: LAURA RENGIFO | B33: Podas Sur | C33: 31 | D33: Aegiphila integrifolia | E33: Pavo; Juan Blanco | F33: Lamiaceae | G33: 31 | H33: =VLOOKUP(F33,'Generos y Familia'!$A$1:$C$623,2,FALSE) -> 34 | I33: =D33 -> Aegiphila integrifolia | J33: =G33&" "&D33 -> 31 Aegiphila integrifolia | K33: =E33 -> Pavo; Juan Blanco | L33: =G33&" "&E33 -> 31 Pavo; Juan Blanco | M33: Nativa | N33: Si | O33: Árbol | P33: Aegiphila
A34: LAURA RENGIFO | B34: Podas Sur | C34: 32 | D34: Aegiphila mollis | E34: Contraculebra de Venezuela | F34: Lamiaceae | G34: 32 | H34: =VLOOKUP(F34,'Generos y Familia'!$A$1:$C$623,2,FALSE) -> 34 | I34: =D34 -> Aegiphila mollis | J34: =G34&" "&D34 -> 32 Aegiphila mollis | K34: =E34 -> Contraculebra de Venezuela | L34: =G34&" "&E34 -> 32 Contraculebra de Venezuela | M34: Introducida | N34: Si | O34: Arbusto | P34: Aegiphila
A35: LAURA RENGIFO | B35: Podas Sur | C35: 33 | D35: Aegiphila panamensis | E35: Loro | F35: Lamiaceae | G35: 33 | H35: =VLOOKUP(F35,'Generos y Familia'!$A$1:$C$623,2,FALSE) -> 34 | I35: =D35 -> Aegiphila panamensis | J35: =G35&" "&D35 -> 33 Aegiphila panamensis | K35: =E35 -> Loro | L35: =G35&" "&E35 -> 33 Loro | M35: Nativa | N35: Si | O35: Árbol | P35: Aegiphila
A36: LAURA RENGIFO | B36: Podas Sur | C36: 34 | D36: Aegiphila sp | E36: Tabaquillo; Palo Blanco; Mantequillo; Sapo de Vieja | F36: Lamiaceae | G36: 34 | H36: =VLOOKUP(F36,'Generos y Familia'!$A$1:$C$623,2,FALSE) -> 34 | I36: =D36 -> Aegiphila sp | J36: =G36&" "&D36 -> 34 Aegiphila sp | K36: =E36 -> Tabaquillo; Palo Blanco; Mantequillo; Sapo de Vieja | L36: =G36&" "&E36 -> 34 Tabaquillo; Palo Blanco; Mantequillo; Sapo de Vieja | M36: Nativa | N36: Si | O36: Árbol | P36: Aegiphila | Q36: 15-20 | R36: (UEIA & USFS, 2018) | S36: 30 | U36: Rápida | W36: 15 | X36: Diámetro y/o altura aproximado por género
A37: LAURA RENGIFO | B37: Podas Sur | C37: 35 | D37: Agave americana | E37: Motua; Chaguar; Maguey | F37: Asparagaceae | G37: 35 | H37: =VLOOKUP(F37,'Generos y Familia'!$A$1:$C$623,2,FALSE) -> 15 | I37: =D37 -> Agave americana | J37: =G37&" "&D37 -> 35 Agave americana | K37: =E37 -> Motua; Chaguar; Maguey | L37: =G37&" "&E37 -> 35 Motua; Chaguar; Maguey | M37: Introducida | N37: Si | O37: Roseta | P37: Agave
A38: LAURA RENGIFO | B38: Podas Sur | C38: 36 | D38: Agave attenuata | E38: Maguey del Dragón | F38: Asparagaceae | G38: 36 | H38: =VLOOKUP(F38,'Generos y Familia'!$A$1:$C$623,2,FALSE) -> 15 | I38: =D38 -> Agave attenuata | J38: =G38&" "&D38 -> 36 Agave attenuata | K38: =E38 -> Maguey del Dragón | L38: =G38&" "&E38 -> 36 Maguey del Dragón | M38: Introducida | N38: Si | O38: Roseta | P38: Agave | Q38: 3 | S38: 30 | U38: Lenta | X38: Diámetro y/o altura aproximado por género
A39: LAURA RENGIFO | B39: Podas Sur | C39: 37 | D39: Agave sp | E39: Pita; Pitera; Magüey | F39: Asparagaceae | G39: 37 | H39: =VLOOKUP(F39,'Generos y Familia'!$A$1:$C$623,2,FALSE) -> 15 | I39: =D39 -> Agave sp | J39: =G39&" "&D39 -> 37 Agave sp | K39: =E39 -> Pita; Pitera; Magüey | L39: =G39&" "&E39 -> 37 Pita; Pitera; Magüey | M39: Introducida | N39: Si | O39: Roseta | P39: Agave
A40: LAURA RENGIFO | B40: Podas Sur | C40: 38 | D40: Aiouea sp | E40: Laurel Feve | F40: Lauraceae | G40: 38 | H40: =VLOOKUP(F40,'Generos y Familia'!$A$1:$C$623,2,FALSE) -> 35 | I40: =D40 -> Aiouea sp | J40: =G40&" "&D40 -> 38 Aiouea sp | K40: =E40 -> Laurel Feve | L40: =G40&" "&E40 -> 38 Laurel Feve | M40: Nativa | N40: Si | O40: Arbusto | P40: Aiouea
...

Sheet Registros retirados
A1: # Eliminados | C1: Motivo | D1: Nuevos #
A2: 1312 | B2: Acacia amarilla | C2: cambio por | D2: 197
A3: 367 | B3: Cordyline Terminalis | C3: cambio por | D3: 430
A4: 1066 | C4: eliminado x duplicación
A5: 313 | B5: citrus x limon | C5: cambiado por | D5: 1178
A6: 92 | C6: eliminado x duplicación
A7: 1066 | C7: eliminado x duplicación
A8: 1278 | C8: eliminado x duplicación
A9: 741 | C9: cambio por | D9: 1218
A10: 1176 | B10: Callistemon speciosus | C10: Cambio por | D10: 215
A11: 1260 | C11: eliminado x duplicación
A12: 1312 | C12: eliminado x duplicación
A13: 1318 | C13: eliminado x duplicación

Sheet Paulina
A1: Nombre Científico corregido | B1: Nombre común | C1: Familia | D1: Origen | E1: ¿Hay reportes en Colombia? | F1: Hábito
A2: Abatia parviflora | B2: Duraznillo; Chirlobirlo; Sacaojos colorado | C2: Salicaceae | D2: Nativa | E2: Si | F2: Árbol
A3: Annona sp. | B3: Anón | C3: Annonaceae | D3: Nativa | E3: Si | F3: Árbol
A5: Araucaria heterophylla | B5: Araucaria; Araucaria real | C5: Araucariaceae | D5: Introducida | E5: Si | F5: Árbol
A7: Baccharis sp. | B7: Chilco | C7: Asteraceae | D7: Nativa | E7: Si | F7: Arbusto
A8: Bambusa sp. | B8: Bambú | C8: Poaceae | D8: Introducida | E8: Si | F8: Bambú y guaduas
A9: Bejaria aestuans | B9: Carbonero de monte; Pegamosco | C9: Ericaceae | D9: Nativa | E9: Si | F9: Árbol
A10: Bocconia frutescens | B10: Trompeto; Curador | C10: Papaveraceae | D10: Nativa | E10: Si | F10: Arbusto
A11: Bougainvillea sp. | B11: Veranera; Curazao | C11: Nyctaginaceae | D11: Introducida | E11: Si | F11: Arbusto
A12: Bougainvillea spectabilis | B12: Veranera; Curazao | C12: Nyctaginaceae | D12: Introducida | E12: Si | F12: Arbusto
A13: Brugmansia candida | B13: Borrachero; Borrachero blanco | C13: Solanaceae | D13: Nativa | E13: Si | F13: Arbusto
A14: Brunellia sp. | B14: Cedrillo | C14: Brunelliaceae
A15: Brunfelsia australis | B15: Francesino; Jazmín de Malabar | C15: Solanaceae | D15: Introducida | E15: Si | F15: Arbusto
A17: Caesalpinia pluviosa | B17: Acacia amarilla | C17: Fabaceae | D17: Introducida | E17: Si | F17: Árbol
A18: Callistemon speciosus | B18: Escobillón rojo | C18: Myrtaceae | D18: Introducida | E18: Si | F18: Árbol
A19: Casimiroa edulis | B19: Mango matasano | C19: Rutaceae | D19: Introducida | E19: Si | F19: Árbol
A20: Cassia sp. | B20: Cañafístula; Acacia | C20: Fabaceae | D20: Nativa | E20: Si | F20: Árbol
A21: Citrus limon | B21: Limón; Limón dulce | C21: Rutaceae | D21: Introducida | E21: Si | F21: Arbusto
A22: Citrus maxima | B22: Toronja; Toronjo; Pomelo; Pamplemusa | C22: Rutaceae | D22: Introducida | E22: Si | F22: Arbusto
A23: Clethra fagifolia | B23: Chiriguaco; Cargagua; Ahuyamo | C23: Clethraceae | D23: Nativa | E23: Si | F23: Árbol
A24: Clusia ducuoides | B24: Chagualo; Chagualito | C24: Clusiaceae | D24: Nativa | E24: Si | F24: Árbol
A25: Clusia trochiformis | B25: Chagualo | C25: Clusiaceae | D25: Nativa | E25: Si | F25: Arbusto
A26: Coffea sp. | B26: Café; Cafeto | C26: Rubiaceae
A27: Crotalaria micans | B27: Cascabelito; Guache; Chucho | C27: Fabaceae | D27: Introducida | E27: Si | F27: Arbusto
A28: Cupressus macrocarpa | B28: Ciprés; Pino; Pino limon | C28: Cupressaceae | D28: Introducida | E28: Si | F28: Árbol
A29: Cycas sp. | B29: Palma cica; Cyca; Cica; Palma de sagú | C29: Cycadaceae | D29: Introducida | E29: Si | F29: Palma
A30: Daphnopsis caracasana | B30: Guasco; Granado; Mote | C30: Thymelaeaceae | D30: Nativa | E30: Si | F30: Arbusto
A31: Dombeya cayeuxii | B31: Dombeya | C31: Malvaceae | D31: Introducida | E31: Si | F31: Arbusto
A32: Drimys granadensis | B32: Canelo de páramo; Ají de páramo; Canelo | C32: Winteraceae | D32: Nativa | E32: Si | F32: Árbol
A33: Duranta erecta | B33: Adonis; Totocal; Totocá; Espino | C33: Verbenaceae | D33: Nativa | E33: Si | F33: Arbusto
A34: Duranta sp. | B34: Duranta | C34: Verbenaceae
A35: Erythrina costaricensis | B35: Chocho; Gachingo; Secó | C35: Fabaceae | D35: Nativa | E35: Si | F35: Árbol
A36: Escallonia paniculata | B36: Chilco colorado; Chilco; Carbón; Tíbar | C36: Escalloniaceae | D36: Nativa | E36: Si | F36: Árbol
A37: Eugenia sp. | B37: Eugenia; Grosello | C37: Myrtaceae
A39: Ficus cyathistipula | B39: Ficus bomba | C39: Moraceae | D39: Introducida | E39: Si | F39: Arbusto
A40: Ficus brevibracteata | B40: Caucho; Higuerón | C40: Moraceae | D40: Nativa | E40: Si | F40: Árbol
A41: Freziera sp. | B41: Cerezo de monte | C41: Pentaphylacaceae
A42: Furcraea sp. | B42: Fique | C42: Asparagaceae
A43: Furcraea andina | B43: Fique; Cabuya; Maguey | C43: Asparagaceae | D43: Nativa | E43: Si | F43: Roseta
A44: Geissanthus kalbreyeri | B44: Colorado; Cucharo | C44: Myrsinaceae | D44: Nativa | E44: Si | F44: Árbol
...

Sheet RN
A1: Archontophoenix cunninghamiana | B1: 2712
A2: Lafoensia acuminata | B2: 1116
A3: Syzygium paniculata | B3: 943
A4: Psidium guajava | B4: 573
A5: Spathodea campanulata | B5: 561
A6: Handroanthus chrysanthus | B6: 494
A7: Cupressus sempervirens | B7: 454
A8: Hibiscus rosa-sinensis | B8: 448
A9: Eucalyptus grandis | B9: 445
A10: Fraxinus udhei | B10: 420
A11: Persea americana | B11: 394
A12: Yucca gigantea | B12: 366
... A440: Camelia sp. | B440: 1

Sheet Tablas

Sheet Nombres cientificos con #
A1: 00 Indeterminado
A2: 1 Abarema jupunba
A3: 2 Abarema sp
A4: 3 Abelmoschus moschatus
A5: 4 Abutilon insigne
A6: 5 Abutilon pictum
A7: 6 Abutilon sp
A8: 7 Acacia angustissima
A9: 8 Acacia baileyana
A10: 9 Acacia caven
A11: 10 Acacia decurrens
A12: 11 Acacia farnesiana
... A1301: 1326 Theobroma speciosum

Sheet Nombres comunes con #
A1: 00 Indeterminado
A2: 1 Frijolillo; Rayo; Guacamayo Blanco; Carbonero; Arenillo de Monte Chocho
A3: 2 Abarema
A4: 3 Hibisco
A5: 4 Abutilon
A6: 5 Faroolito Japones
A7: 6 Abutilon
A8: 7 Dormilón
A9: 8 Acacia (Baileyana)
A10: 9 Aromo
A11: 10 Acacia Roja (Decurrens)
A12: 11 Acacia de Desierto; Acacia Farnesiana
... A1301: 1326 Cacao silvestre; Cacao de Monte

Sheet Generos y Familia
A1: Familia | B1: Número de Familia | C1: Género | F1: Familia | G1: Genero | I1: Familia | K1: Genero | M1: Familia | N1: _# de Familia | P1: # y familia | R1: # y género
A2: Acanthaceae | B2: 1 | C2: Aphelandra | F2: Acanthaceae | I2: Acanthaceae | K2: Abarema | M2: Acanthaceae | N2: 1 | P2: =N2&". "&M2 -> 1. Acanthaceae | R2: =B2&". "&C2 -> 1. Aphelandra
A3: Acanthaceae | B3: 1 | C3: Asystasia | G3: Aphelandra | I3: Achatocarpaceae | K3: Abatia | M3: Achatocarpaceae | N3: 2 | P3: =N3&". "&M3 -> 2. Achatocarpaceae | R3: =B3&". "&C3 -> 1. Asystasia
A4: Acanthaceae | B4: 1 | C4: Dianthera | G4: Asystasia | I4: Actinidiaceae | K4: Abelmoschus | M4: Actinidiaceae | N4: 3 | P4: =N4&". "&M4 -> 3. Actinidiaceae | R4: =B4&". "&C4 -> 1. Dianthera
A5: Acanthaceae | B5: 1 | C5: Graptophyllum | G5: Dianthera | I5: Adoxaceae | K5: Abutilon | M5: Adoxaceae | N5: 4 | P5: =N5&". "&M5 -> 4. Adoxaceae | R5: =B5&". "&C5 -> 1. Graptophyllum
A6: Acanthaceae | B6: 1 | C6: Justicia | G6: Graptophyllum | I6: Altingiaceae | K6: Acacia | M6: Altingiaceae | N6: 5 | P6: =N6&". "&M6 -> 5. Altingiaceae | R6: =B6&". "&C6 -> 1. Justicia
A7: Acanthaceae | B7: 1 | C7: Megaskepasma | G7: Justicia | I7: Amaranthaceae | K7: Acalypha | M7: Amaranthaceae | N7: 6 | P7: =N7&". "&M7 -> 6. Amaranthaceae | R7: =B7&". "&C7 -> 1. Megaskepasma
A8: Acanthaceae | B8: 1 | C8: Pachystachys | G8: Megaskepasma | I8: Amaryllidaceae | K8: Acca | M8: Amaryllidaceae | N8: 7 | P8: =N8&". "&M8 -> 7. Amaryllidaceae | R8: =B8&". "&C8 -> 1. Pachystachys
A9: Acanthaceae | B9: 1 | C9: Pseuderanthemum | G9: Pachystachys | I9: Anacardiaceae | K9: Achatocarpus | M9: Anacardiaceae | N9: 7 | P9: =N9&". "&M9 -> 7. Anacardiaceae | R9: =B9&". "&C9 -> 1. Pseuderanthemum
A10: Acanthaceae | B10: 1 | C10: Ruellia | G10: Pseuderanthemum | I10: Annonaceae | K10: Achyranthes | M10: Annonaceae | N10: 8 | P10: =N10&". "&M10 -> 8. Annonaceae | R10: =B10&". "&C10 -> 1. Ruellia
A11: Acanthaceae | B11: 1 | C11: Sanchezia | G11: Ruellia | I11: Apocynaceae | K11: Acnistus | M11: Apocynaceae | N11: 9 | P11: =N11&". "&M11 -> 9. Apocynaceae | R11: =B11&". "&C11 -> 1. Sanchezia
A12: Acanthaceae | B12: 1 | C12: Thunbergia | G12: Sanchezia | I12: Aquifoliaceae | K12: Acosmium | M12: Aquifoliaceae | N12: 10 | P12: =N12&". "&M12 -> 10. Aquifoliaceae | R12: =B12&". "&C12 -> 1. Thunbergia
A13: Acanthaceae | B13: 1 | C13: Trichanthera | G13: Thunbergia | I13: Araceae | K13: Acrocarpus | M13: Araceae | N13: 11 | P13: =N13&". "&M13 -> 11. Araceae | R13: =B13&". "&C13 -> 1. Trichanthera
A14: Achatocarpaceae | B14: 2 | C14: Achatocarpus | G14: Trichanthera | I14: Araliaceae | K14: Acrocomia | M14: Araliaceae | N14: 12 | P14: =N14&". "&M14 -> 12. Araliaceae | R14: =B14&". "&C14 -> 2. Achatocarpus
A15: Actinidiaceae | B15: 3 | C15: Saurauia | F15: Achatocarpaceae | I15: Araucariaceae | K15: Adenanthera | M15: Araucariaceae | N15: 13 | P15: =N15&". "&M15 -> 13. Araucariaceae | R15: =B15&". "&C15 -> 3. Saurauia
A16: Adoxaceae | B16: 4 | C16: Sambucus | G16: Achatocarpus | I16: Arecaceae | K16: Adenaria | M16: Arecaceae | N16: 14 | P16: =N16&". "&M16 -> 14. Arecaceae | R16: =B16&". "&C16 -> 4. Sambucus
A17: Adoxaceae | B17: 4 | C17: Viburnum | F17: Actinidiaceae | I17: Asparagaceae | K17: Adonidia | M17: Asparagaceae | N17: 15 | P17: =N17&". "&M17 -> 15. Asparagaceae | R17: =B17&". "&C17 -> 4. Viburnum
A18: Altingiaceae | B18: 5 | C18: Liquidambar | G18: Saurauia | I18: Asphodelaceae | K18: Aegiceras | M18: Asphodelaceae | N18: 16 | P18: =N18&". "&M18 -> 16. Asphodelaceae | R18: =B18&". "&C18 -> 5. Liquidambar
A19: Amaranthaceae | B19: 6 | C19: Achyranthes | F19: Adoxaceae | I19: Asteraceae | K19: Aegiphila | M19: Asteraceae | N19: 17 | P19: =N19&". "&M19 -> 17. Asteraceae | R19: =B19&". "&C19 -> 6. Achyranthes
A20: Amaranthaceae | B20: 6 | C20: Alternanthera | G20: Sambucus | I20: Begoniaceae | K20: Agave | M20: Begoniaceae | N20: 18 | P20: =N20&". "&M20 -> 18. Begoniaceae | R20: =B20&". "&C20 -> 6. Alternanthera
A21: Amaranthaceae | B21: 6 | C21: Amaranthus | G21: Viburnum | I21: Betulaceae | K21: Ailanthus | M21: Betulaceae | N21: 19 | P21: =N21&". "&M21 -> 19. Betulaceae | R21: =B21&". "&C21 -> 6. Amaranthus
A22: Amaranthaceae | B22: 6 | C22: Aralia | F22: Altingiaceae | I22: Bignoniaceae | K22: Aiouea | M22: Bignoniaceae | N22: 20 | P22: =N22&". "&M22 -> 20. Bignoniaceae | R22: =B22&". "&C22 -> 6. Aralia
A23: Amaranthaceae | B23: 6 | C23: Pleuropetalum | G23: Liquidambar | I23: Bixaceae | K23: Aiphanes | M23: Bixaceae | N23: 21 | P23: =N23&". "&M23 -> 21. Bixaceae | R23: =B23&". "&C23 -> 6. Pleuropetalum
A24: Amaryllidaceae | B24: 7 | C24: Galanthus | F24: Amaranthaceae | I24: Boraginaceae | K24: Albizia | M24: Boraginaceae | N24: 22 | P24: =N24&". "&M24 -> 22. Boraginaceae | R24: =B24&". "&C24 -> 7. Galanthus
A25: Anacardiaceae | B25: 7 | C25: Anacardium | G25: Achyranthes | I25: Brunelliaceae | K25: Alchornea | M25: Brunelliaceae | N25: 23 | P25: =N25&". "&M25 -> 23. Brunelliaceae | R25: =B25&". "&C25 -> 7. Anacardium
A26: Anacardiaceae | B26: 7 | C26: Astronium | G26: Alternanthera | I26: Burseraceae | K26: Aleurites | M26: Burseraceae | N26: 24 | P26: =N26&". "&M26 -> 24. Burseraceae | R26: =B26&". "&C26 -> 7. Astronium
A27: Anacardiaceae | B27: 7 | C27: Mangifera | G27: Amaranthus | I27: Buxaceae | K27: Alfaroa | M27: Buxaceae | N27: 25 | P27: =N27&". "&M27 -> 25. Buxaceae | R27: =B27&". "&C27 -> 7. Mangifera
A28: Anacardiaceae | B28: 7 | C28: Mauria | G28: Aralia | I28: Cactaceae | K28: Alibertia | M28: Cactaceae | N28: 26 | P28: =N28&". "&M28 -> 26. Cactaceae | R28: =B28&". "&C28 -> 7. Mauria
A29: Anacardiaceae | B29: 7 | C29: Ozoroa | G29: Pleuropetalum | I29: Calophyllaceae | K29: Allamanda | M29: Calophyllaceae | N29: 27 | P29: =N29&". "&M29 -> 27. Calophyllaceae | R29: =B29&". "&C29 -> 7. Ozoroa
A30: Anacardiaceae | B30: 7 | C30: Rhus | F30: Amaryllidaceae | I30: Cannabaceae | K30: Allophylus | M30: Cannabaceae | N30: 28 | P30: =N30&". "&M30 -> 28. Cannabaceae | R30: =B30&". "&C30 -> 7. Rhus
A31: Anacardiaceae | B31: 7 | C31: Schinus | G31: Galanthus | I31: Capparaceae | K31: Alnus | M31: Capparaceae | N31: 29 | P31: =N31&". "&M31 -> 29. Capparaceae | R31: =B31&". "&C31 -> 7. Schinus
A32: Anacardiaceae | B32: 7 | C32: Spondias | F32: Anacardiaceae | I32: Caprifoliaceae | K32: Aloe | M32: Caprifoliaceae | N32: 30 | P32: =N32&". "&M32 -> 30. Caprifoliaceae | R32: =B32&". "&C32 -> 7. Spondias
A33: Anacardiaceae | B33: 7 | C33: Tapirira | G33: Anacardium | I33: Caricaceae | K33: Aloysia | M33: Caricaceae | N33: 31 | P33: =N33&". "&M33 -> 31. Caricaceae | R33: =B33&". "&C33 -> 7. Tapirira
A34: Anacardiaceae | B34: 7 | C34: Toxicodendron | G34: Astronium | I34: Caryocaraceae | K34: Alpinia | M34: Caryocaraceae | N34: 32 | P34: =N34&". "&M34 -> 32. Caryocaraceae | R34: =B34&". "&C34 -> 7. Toxicodendron
A35: Annonaceae | B35: 8 | C35: Annona | G35: Mangifera | I35: Casuarinaceae | K35: Alstonia | M35: Casuarinaceae | N35: 33 | P35: =N35&". "&M35 -> 33. Casuarinaceae | R35: =B35&". "&C35 -> 8. Annona
A36: Annonaceae | B36: 8 | C36: Cananga | G36: Mauria | I36: Celastraceae | K36: Alternanthera | M36: Celastraceae | N36: 34 | P36: =N36&". "&M36 -> 34. Celastraceae | R36: =B36&". "&C36 -> 8. Cananga
A37: Annonaceae | B37: 8 | C37: Guatteria | G37: Ozoroa | I37: Chrysobalanaceae | K37: Amaranthus | M37: Chrysobalanaceae | N37: 35 | P37: =N37&". "&M37 -> 35. Chrysobalanaceae | R37: =B37&". "&C37 -> 8. Guatteria
A38: Annonaceae | B38: 8 | C38: Monoon | G38: Rhus | I38: Clethraceae | K38: Amherstia | M38: Clethraceae | N38: 36 | P38: =N38&". "&M38 -> 36. Clethraceae | R38: =B38&". "&C38 -> 8. Monoon
A39: Annonaceae | B39: 8 | C39: Rollinia | G39: Schinus | I39: Clusiaceae | K39: Ampelocera | M39: Clusiaceae | N39: 37 | P39: =N39&". "&M39 -> 37. Clusiaceae | R39: =B39&". "&C39 -> 8. Rollinia
A40: Annonaceae | B40: 8 | C40: Salicaceae | G40: Spondias | I40: Cochlospermaceae | K40: Amphitecna | M40: Cochlospermaceae | N40: 38 | P40: =N40&". "&M40 -> 38. Cochlospermaceae | R40: =B40&". "&C40 -> 8. Salicaceae
...

Sheet Validación
C2: Definiciones usadas en Savia Servicios SAS ESP.
C3: Hábitos de crecimiento | D3: Definición
C4: Arbusto | D4: Plantas leñosas con múltiples tallos que generalmente son más cortos que los árboles. Hasta 5 metros de altura
C5: Árbol | D5: Plantas leñosas con un solo tallo principal o tronco que generalmente crece verticalmente y tiene ramificaciones superiores.
C6: Palma | D6: Palnta que crece a partir de uno o varios tallos con una corona de hojas agrupadas en el extremo del tallo. Se pueden incluir familias como Arecaceae, Cycadaceae y Asparagaceae
C7: Epífita | D7: Plantas que crecen sobre otras plantas, usualmente en árboles, sin ser parásitas, obtienen sus nutrientes del aire y de materia orgánica acumulada.
C8: Hierba | D8: Plantas herbáceas con tallos suaves y flexibles, generalmente de porte bajo y con ciclos de vida cortos.
C9: Trepadora | D9: Plantas que no pueden mantenerse erguidas por sí mismas y se apoyan en otras estructuras para crecer verticalmente.
C10: Roseta | D10: Plantas con hojas dispuestas en una forma circular alrededor de una base central.
C11: Saprófita | D11: Plantas que obtienen su nutrición de la materia orgánica muerta en descomposición en el suelo.
C12: Hemiparásita | D12: Plantas que obtienen parte de sus nutrientes a través de la conexión con las raíces de otras plantas, pero aún son capaces de realizar fotosíntesis.
C13: Parasita | D13: Plantas que obtienen todos sus nutrientes de otras plantas a través de conexiones especializadas, a menudo perjudicando a su hospedador.
C14: Flotante | D14: Plantas que crecen sobre la superficie del agua sin estar arraigadas en el suelo.
... C20: Hidrófita | D20: Plantas adaptadas a ambientes acuáticos o sumergidos.
C21: Bambú y guaduas
C22: No definido
C24: Origen
C25: Nativa | D25: Colombia, región del norte de sur America y Centro america
C26: Introducida | D26: Que colombia no está dentro de su zona de distribución natural
C27: Endemica | D27: Exclusiva de la región
C28: No definido
C29: Proyecto
C30: Otro
C31: Podas Sur
C32: Podas Cartago
C33: Podas Rionegro

Sheet Fuente de consulta
B2: Nombres científicos | C2: Nombres comunes
A3: Herbario | B3: http://www.biovirtual.unal.edu.co/es/colecciones/search/plants/ | C3: http://www.biovirtual.unal.edu.co/nombrescomunes/es/
A4: Taxones internacionales | B4: https://wfoplantlist.org/ | C4: https://catalogofloravalleaburra.eia.edu.co/species/scientific-name
A5: Distribución en Colombia | B5: https://biodiversidad.co/data/?taxonKey=2735935 | C5: https://catalogoarbolesurbanos.eia.edu.co/
B9: Si
B10: No
B11: No definible
A36: (UEIA, 2014) | B36: UEIA. (2014). Catálogo virtual de flora de Alta Montaña. Grupo de Investigación, Sostenibilidad, Infraestructura y Territorio (SITE). https://catalogofloraaltamontana.eia.edu.co/species/250
A38: (UEIA, 2014) | B38: UEIA. (2014). Catálogo virtual de flora del Valle del Aburra. Grupo de Investigación, Sostenibilidad, Infraestructura y Territorio (SITE). https://catalogofloraaltamontana.eia.edu.co/species/250
A40: (UEIA & USFS, 2018) | B40: UEIA & USFS. (2018). Catálogo de árboles urbanos de Colombia.
A41: (Benedetti, 2012) | B41: Benedetti, S. (2012). Monografía de Espino Acacia caven (Mol.)Mol. Programa de invenstigación de productos forestales.Instituto Forestal. Chile.
A43: (NaturalisCO, 2024)
B44: Rodríguez Bonet, Sergio, Chaparro Aguilera, Laura, Benítez Villalba, Julio, Villalba, Domitila, Arévalos Rotela, Laura, & Benítez Franco, Rossana. (2020). Caracterización fisicoquímica de la pulpa y almendra de Acrocomia aculeata. Investigación Agraria, 22(1), 46-52. Epub June 00, 2020.https://doi.org/10.18004/investig.agrar.2020.junio.46-52
A48: (Catálogo de la Biodiversidad, 2024) | B48: https://catalogo.biodiversidad.co/file/56d0c6343c16479905cba835/summary
A49: (iNaturalistEc, 2024)
A50: (Varón & Morales, 2014) | B50: Varón, T. Morales, L. (2014). Arboretum y Palmetum, guía de identificación. Universidad Nacional de Colombia.
